ERROR 2018-04-13 14:20:09,973 exception:handle_uncaught_exception:135 Internal Server Error: /admin/
Traceback (most recent call last):
  File "/usr/local/PythonVirtualENV/MyTestENV/lib/python2.7/site-packages/django/core/handlers/exception.py", line 41, in inner
    response = get_response(request)
  File "/usr/local/PythonVirtualENV/MyTestENV/lib/python2.7/site-packages/django/core/handlers/base.py", line 249, in _legacy_get_response
    response = self._get_response(request)
  File "/usr/local/PythonVirtualENV/MyTestENV/lib/python2.7/site-packages/django/core/handlers/base.py", line 187, in _get_response
    response = self.process_exception_by_middleware(e, request)
  File "/usr/local/PythonVirtualENV/MyTestENV/lib/python2.7/site-packages/django/core/handlers/base.py", line 185, in _get_response
    response = wrapped_callback(request, *callback_args, **callback_kwargs)
  File "/usr/local/PythonVirtualENV/MyTestENV/lib/python2.7/site-packages/django/contrib/admin/sites.py", line 242, in wrapper
    return self.admin_view(view, cacheable)(*args, **kwargs)
  File "/usr/local/PythonVirtualENV/MyTestENV/lib/python2.7/site-packages/django/utils/decorators.py", line 149, in _wrapped_view
    response = view_func(request, *args, **kwargs)
  File "/usr/local/PythonVirtualENV/MyTestENV/lib/python2.7/site-packages/django/views/decorators/cache.py", line 57, in _wrapped_view_func
    response = view_func(request, *args, **kwargs)
  File "/usr/local/PythonVirtualENV/MyTestENV/lib/python2.7/site-packages/django/contrib/admin/sites.py", line 213, in inner
    if not self.has_permission(request):
  File "/usr/local/PythonVirtualENV/MyTestENV/lib/python2.7/site-packages/django/contrib/admin/sites.py", line 187, in has_permission
    return request.user.is_active and request.user.is_staff
  File "/usr/local/PythonVirtualENV/MyTestENV/lib/python2.7/site-packages/django/utils/functional.py", line 238, in inner
    self._setup()
  File "/usr/local/PythonVirtualENV/MyTestENV/lib/python2.7/site-packages/django/utils/functional.py", line 386, in _setup
    self._wrapped = self._setupfunc()
  File "/usr/local/PythonVirtualENV/MyTestENV/lib/python2.7/site-packages/django/contrib/auth/middleware.py", line 24, in <lambda>
    request.user = SimpleLazyObject(lambda: get_user(request))
  File "/usr/local/PythonVirtualENV/MyTestENV/lib/python2.7/site-packages/django/contrib/auth/middleware.py", line 12, in get_user
    request._cached_user = auth.get_user(request)
  File "/usr/local/PythonVirtualENV/MyTestENV/lib/python2.7/site-packages/django/contrib/auth/__init__.py", line 211, in get_user
    user_id = _get_user_session_key(request)
  File "/usr/local/PythonVirtualENV/MyTestENV/lib/python2.7/site-packages/django/contrib/auth/__init__.py", line 61, in _get_user_session_key
    return get_user_model()._meta.pk.to_python(request.session[SESSION_KEY])
  File "/usr/local/PythonVirtualENV/MyTestENV/lib/python2.7/site-packages/django/contrib/sessions/backends/base.py", line 57, in __getitem__
    return self._session[key]
  File "/usr/local/PythonVirtualENV/MyTestENV/lib/python2.7/site-packages/django/contrib/sessions/backends/base.py", line 207, in _get_session
    self._session_cache = self.load()
  File "/usr/local/PythonVirtualENV/MyTestENV/lib/python2.7/site-packages/django/contrib/sessions/backends/db.py", line 35, in load
    expire_date__gt=timezone.now()
  File "/usr/local/PythonVirtualENV/MyTestENV/lib/python2.7/site-packages/django/db/models/manager.py", line 85, in manager_method
    return getattr(self.get_queryset(), name)(*args, **kwargs)
  File "/usr/local/PythonVirtualENV/MyTestENV/lib/python2.7/site-packages/django/db/models/query.py", line 374, in get
    num = len(clone)
  File "/usr/local/PythonVirtualENV/MyTestENV/lib/python2.7/site-packages/django/db/models/query.py", line 232, in __len__
    self._fetch_all()
  File "/usr/local/PythonVirtualENV/MyTestENV/lib/python2.7/site-packages/django/db/models/query.py", line 1118, in _fetch_all
    self._result_cache = list(self._iterable_class(self))
  File "/usr/local/PythonVirtualENV/MyTestENV/lib/python2.7/site-packages/django/db/models/query.py", line 53, in __iter__
    results = compiler.execute_sql(chunked_fetch=self.chunked_fetch)
  File "/usr/local/PythonVirtualENV/MyTestENV/lib/python2.7/site-packages/django/db/models/sql/compiler.py", line 899, in execute_sql
    raise original_exception
ProgrammingError: (1146, "Table 'jdops.django_session' doesn't exist")
ERROR 2018-04-13 14:20:13,037 exception:handle_uncaught_exception:135 Internal Server Error: /admin/
Traceback (most recent call last):
  File "/usr/local/PythonVirtualENV/MyTestENV/lib/python2.7/site-packages/django/core/handlers/exception.py", line 41, in inner
    response = get_response(request)
  File "/usr/local/PythonVirtualENV/MyTestENV/lib/python2.7/site-packages/django/core/handlers/base.py", line 249, in _legacy_get_response
    response = self._get_response(request)
  File "/usr/local/PythonVirtualENV/MyTestENV/lib/python2.7/site-packages/django/core/handlers/base.py", line 187, in _get_response
    response = self.process_exception_by_middleware(e, request)
  File "/usr/local/PythonVirtualENV/MyTestENV/lib/python2.7/site-packages/django/core/handlers/base.py", line 185, in _get_response
    response = wrapped_callback(request, *callback_args, **callback_kwargs)
  File "/usr/local/PythonVirtualENV/MyTestENV/lib/python2.7/site-packages/django/contrib/admin/sites.py", line 242, in wrapper
    return self.admin_view(view, cacheable)(*args, **kwargs)
  File "/usr/local/PythonVirtualENV/MyTestENV/lib/python2.7/site-packages/django/utils/decorators.py", line 149, in _wrapped_view
    response = view_func(request, *args, **kwargs)
  File "/usr/local/PythonVirtualENV/MyTestENV/lib/python2.7/site-packages/django/views/decorators/cache.py", line 57, in _wrapped_view_func
    response = view_func(request, *args, **kwargs)
  File "/usr/local/PythonVirtualENV/MyTestENV/lib/python2.7/site-packages/django/contrib/admin/sites.py", line 213, in inner
    if not self.has_permission(request):
  File "/usr/local/PythonVirtualENV/MyTestENV/lib/python2.7/site-packages/django/contrib/admin/sites.py", line 187, in has_permission
    return request.user.is_active and request.user.is_staff
  File "/usr/local/PythonVirtualENV/MyTestENV/lib/python2.7/site-packages/django/utils/functional.py", line 238, in inner
    self._setup()
  File "/usr/local/PythonVirtualENV/MyTestENV/lib/python2.7/site-packages/django/utils/functional.py", line 386, in _setup
    self._wrapped = self._setupfunc()
  File "/usr/local/PythonVirtualENV/MyTestENV/lib/python2.7/site-packages/django/contrib/auth/middleware.py", line 24, in <lambda>
    request.user = SimpleLazyObject(lambda: get_user(request))
  File "/usr/local/PythonVirtualENV/MyTestENV/lib/python2.7/site-packages/django/contrib/auth/middleware.py", line 12, in get_user
    request._cached_user = auth.get_user(request)
  File "/usr/local/PythonVirtualENV/MyTestENV/lib/python2.7/site-packages/django/contrib/auth/__init__.py", line 211, in get_user
    user_id = _get_user_session_key(request)
  File "/usr/local/PythonVirtualENV/MyTestENV/lib/python2.7/site-packages/django/contrib/auth/__init__.py", line 61, in _get_user_session_key
    return get_user_model()._meta.pk.to_python(request.session[SESSION_KEY])
  File "/usr/local/PythonVirtualENV/MyTestENV/lib/python2.7/site-packages/django/contrib/sessions/backends/base.py", line 57, in __getitem__
    return self._session[key]
  File "/usr/local/PythonVirtualENV/MyTestENV/lib/python2.7/site-packages/django/contrib/sessions/backends/base.py", line 207, in _get_session
    self._session_cache = self.load()
  File "/usr/local/PythonVirtualENV/MyTestENV/lib/python2.7/site-packages/django/contrib/sessions/backends/db.py", line 35, in load
    expire_date__gt=timezone.now()
  File "/usr/local/PythonVirtualENV/MyTestENV/lib/python2.7/site-packages/django/db/models/manager.py", line 85, in manager_method
    return getattr(self.get_queryset(), name)(*args, **kwargs)
  File "/usr/local/PythonVirtualENV/MyTestENV/lib/python2.7/site-packages/django/db/models/query.py", line 374, in get
    num = len(clone)
  File "/usr/local/PythonVirtualENV/MyTestENV/lib/python2.7/site-packages/django/db/models/query.py", line 232, in __len__
    self._fetch_all()
  File "/usr/local/PythonVirtualENV/MyTestENV/lib/python2.7/site-packages/django/db/models/query.py", line 1118, in _fetch_all
    self._result_cache = list(self._iterable_class(self))
  File "/usr/local/PythonVirtualENV/MyTestENV/lib/python2.7/site-packages/django/db/models/query.py", line 53, in __iter__
    results = compiler.execute_sql(chunked_fetch=self.chunked_fetch)
  File "/usr/local/PythonVirtualENV/MyTestENV/lib/python2.7/site-packages/django/db/models/sql/compiler.py", line 899, in execute_sql
    raise original_exception
ProgrammingError: (1146, "Table 'jdops.django_session' doesn't exist")
